[ERROR]15:36:08:610-caseLogs.py:49 >> 接口出问题了
